<?xml version="1.0" ?>
<!-- =================================================================================== -->
<!-- |    This document was autogenerated by xacro from puma560_robot.urdf.xacro       | -->
<!-- |    EDITING THIS FILE BY HAND IS NOT RECOMMENDED                                 | -->
<!-- =================================================================================== -->
<robot name="4DOF_Robot">
  <!-- DH Paramaters -->
  <link name="base" />

  <!-- Robot 1 -->
  <link name="link1" />
  <link name="link2" />
  <link name="link3" />
  <link name="link4" />
  <link name="link5" />
  <link name="link6" />

  <joint name="fixed" type="fixed">
    <parent link="base" />
    <child link="link1" />
    <origin rpy="0 0 0" xyz="0 0 0" />
  </joint>

  <joint name="j1" type="revolute">
    <parent link="link1" />
    <child link="link2" />
    <origin rpy="0 0 0" xyz="0 0 0.4" />
    <axis xyz="0 0 1" />
  </joint>

  <joint name="j2" type="revolute">
    <parent link="link2"/>
    <child link="link3"/>
    <origin rpy="-1.57 0 0" xyz="0 0.1 0"/>
    <axis xyz="0 0 1"/>
  </joint>

  <joint name="j3" type="revolute">
    <parent link="link3"/>
    <child link="link4"/>
    <origin rpy="0 0 1.57" xyz="0.4 0 0"/>
    <axis xyz="0 0 1"/>
  </joint>

  <joint name="j4" type="revolute">
    <parent link="link4"/>
    <child link="link5"/>
    <origin rpy="0 0 -1.57" xyz="0.3 0 0"/>
    <axis xyz="0 0 1"/>
  </joint>

  <joint name="j5" type="fixed">
    <parent link="link5"/>
    <child link="link6"/>
    <origin rpy="0 0 0" xyz="0.2 0 0"/>
  </joint>

  <!-- Robot 2 -->
  <link name="link1_2" />
  <link name="link2_2" />
  <link name="link3_2" />
  <link name="link4_2" />
  <link name="link5_2" />
  <link name="link6_2" />

  <joint name="fixed" type="fixed">
    <parent link="base" />
    <child link="link1_2" />
    <origin rpy="0 0 -1.57" xyz="1 1 0" />
  </joint>

  <joint name="j1_2" type="revolute">
    <parent link="link1_2" />
    <child link="link2_2" />
    <origin rpy="0 0 0" xyz="0 0 0.4" />
    <axis xyz="0 0 1" />
  </joint>

  <joint name="j2_2" type="revolute">
    <parent link="link2_2"/>
    <child link="link3_2"/>
    <origin rpy="-1.57 0 0" xyz="0 0.1 0"/>
    <axis xyz="0 0 1"/>
  </joint>

  <joint name="j3_2" type="revolute">
    <parent link="link3_2"/>
    <child link="link4_2"/>
    <origin rpy="0 0 1.57" xyz="0.4 0 0"/>
    <axis xyz="0 0 1"/>
  </joint>

  <joint name="j4_2" type="revolute">
    <parent link="link4_2"/>
    <child link="link5_2"/>
    <origin rpy="0 0 -1.57" xyz="0.3 0 0"/>
    <axis xyz="0 0 1"/>
  </joint>

  <joint name="j5_2" type="fixed">
    <parent link="link5_2"/>
    <child link="link6_2"/>
    <origin rpy="0 0 0" xyz="0.2 0 0"/>
  </joint>
</robot>

